<?xml version="1.0" ?>
<robot name="gimbal_small_2d">
  <joint name="gimbal_small_2d__tilt_joint" type="revolute">
    <parent link="gimbal_small_2d__base_link"/>
    <child link="gimbal_small_2d__tilt_link"/>
    <origin rpy="0  0  0" xyz="0   0   0.2"/>
    <axis xyz="1  0  0"/>
    <limit effort="10.0" lower="-0.1" upper="3.14159265" velocity="0"/>
  </joint>
  <link name="gimbal_small_2d__base_link">
    <inertial>
      <mass value="0.2"/>
      <origin rpy="0  0  0" xyz="0  0  0"/>
      <inertia ixx="0.0001" ixy="0" ixz="0" iyy="0.0001" iyz="0" izz="0.0001"/>
    </inertial>
    <collision name="gimbal_small_2d__base_col">
      <origin rpy="0  0  0" xyz="0.01   0.075  0.155"/>
      <geometry>
        <box size="0.1 0.05 0.15"/>
      </geometry>
    </collision>
    <visual name="gimbal_small_2d__base_main_viz">
      <origin rpy="0  0  0" xyz="0    0    0.18"/>
      <geometry>
        <mesh filename="package://interiit21/models/gimbal_small_2d/meshes/base_main.dae" scale="0.001 0.001 0.001"/>
      </geometry>
    </visual>
    <visual name="gimbal_small_2d__base_arm_viz">
      <origin rpy="0  0  0" xyz="0    0    0.18"/>
      <geometry>
        <mesh filename="package://interiit21/models/gimbal_small_2d/meshes/base_arm.dae" scale="0.001 0.001 0.001"/>
      </geometry>
    </visual>
  </link>
  <link name="gimbal_small_2d__tilt_link">
    <inertial>
      <mass value="0.01"/>
      <origin rpy="0  0  0" xyz="0  0  0"/>
      <inertia ixx="0.00001" ixy="0" ixz="0" iyy="0.00001" iyz="0" izz="0.00001"/>
    </inertial>
    <collision name="gimbal_small_2d__tilt_col">
      <origin rpy="0  0  0" xyz="0     0    -0.025"/>
      <geometry>
        <mesh filename="package://interiit21/models/gimbal_small_2d/meshes/tilt.dae" scale="0.001 0.001 0.001"/>
      </geometry>
    </collision>
    <collision name="gimbal_small_2d__camera_col">
      <origin rpy="0  0  0" xyz="0  0  0"/>
      <geometry>
        <cylinder length="0.050" radius="0.025"/>
      </geometry>
    </collision>
    <visual name="gimbal_small_2d__tilt_viz">
      <origin rpy="0  0  0" xyz="0     0    -0.025"/>
      <geometry>
        <mesh filename="package://interiit21/models/gimbal_small_2d/meshes/tilt.dae" scale="0.001 0.001 0.001"/>
      </geometry>
    </visual>
    <visual name="gimbal_small_2d__camera_viz">
      <origin rpy="0  0  0" xyz="0  0  0"/>
      <geometry>
        <cylinder length="0.050" radius="0.025"/>
      </geometry>
    </visual>
  </link>
</robot>
